input.in
1
o
0 B 1 LCIL 88 97
0 S 2 LCIL 26 1
0 C 1
0 C 2
0 C 1
0 S 3 LCIL 79 88
0 S 4 LCIL 53 28
0 C 2
0 S 5 LCIL 22 63
0 C 3
0 B 6 LCIL 69 99
0 S 7 LCIL 13 8
0 B 8 LCIL 90 67
0 C 5
0 S 9 LCIL 98 92
0 C 2
0 S 10 LCIL 14 7
0 C 6
0 B 11 LCIL 16 95
0 C 6
0 C 2
0 B 12 LCIL 97 88
0 C 10
0 C 6
0 B 13 LCIL 56 46
0 C 6
0 B 14 LCIL 3 95
0 S 15 LCIL 86 9
0 B 16 LCIL 66 48
0 C 7
0 C 16
0 S 17 LCIL 93 2
0 B 18 LCIL 34 67
0 S 19 LCIL 84 80
0 S 20 LCIL 5 80
0 S 21 LCIL 24 15
0 S 22 LCIL 67 70
0 B 23 LCIL 4 75
0 B 24 LCIL 25 40
0 C 20
0 C 21
0 B 25 LCIL 88 54
0 B 26 LCIL 80 99
0 S 27 LCIL 56 53
0 B 28 LCIL 96 3
0 S 29 LCIL 75 83
0 C 18
0 S 30 LCIL 21 7
0 C 13
0 B 31 LCIL 49 79
0 S 32 LCIL 27 17
0 C 8
0 B 33 LCIL 31 67
0 B 34 LCIL 25 28
0 C 23
0 C 19
0 S 35 LCIL 60 60
0 C 29
0 S 36 LCIL 4 20
0 S 37 LCIL 94 5
0 B 38 LCIL 22 75
0 B 39 LCIL 57 23
0 B 40 LCIL 84 96
0 C 19
0 B 41 LCIL 69 36
0 C 24
0 B 42 LCIL 87 32
0 B 43 LCIL 16 28
0 S 44 LCIL 100 99
0 C 1
0 B 45 LCIL 96 71
0 B 46 LCIL 35 22
0 B 47 LCIL 65 37
0 B 48 LCIL 76 48
0 C 40
0 B 49 LCIL 93 78
0 B 50 LCIL 57 28
0 B 51 LCIL 19 20
0 B 52 LCIL 31 11
0 B 53 LCIL 11 17
0 B 54 LCIL 7 54
0 C 5
0 B 55 LCIL 23 49
0 B 56 LCIL 12 49
0 B 57 LCIL 77 9
0 C 25
0 C 45
0 C 55
0 S 58 LCIL 27 5
0 B 59 LCIL 79 29
0 B 60 LCIL 70 25
0 S 61 LCIL 72 76
0 S 62 LCIL 89 96
0 B 63 LCIL 37 2
0 B 64 LCIL 48 38
0 C 26
0 B 65 LCIL 24 43
0 S 66 LCIL 40 42
0 S 67 LCIL 78 23
0 S 68 LCIL 97 81
0 B 69 LCIL 39 89
0 C 5
0 S 70 LCIL 87 37
0 B 71 LCIL 65 6
0 B 72 LCIL 91 38
0 B 73 LCIL 7 38
0 B 74 LCIL 98 100
0 C 42
0 C 57
0 C 66
0 C 66
0 C 38
0 S 75 LCIL 52 10
0 S 76 LCIL 100 84
0 B 77 LCIL 5 44
0 S 78 LCIL 71 96
0 S 79 LCIL 36 60
0 B 80 LCIL 29 3
0 B 81 LCIL 24 89
0 C 4
0 S 82 LCIL 14 73
0 S 83 LCIL 59 53
0 S 84 LCIL 88 77
0 B 85 LCIL 24 32
0 S 86 LCIL 29 17
0 S 87 LCIL 12 71
0 S 88 LCIL 24 100
0 C 88
0 C 23
0 B 89 LCIL 70 77
0 C 66
0 C 20
0 B 90 LCIL 95 86
0 C 37
0 B 91 LCIL 65 63
0 S 92 LCIL 29 59
0 C 40
0 B 93 LCIL 100 50
0 C 3
0 S 94 LCIL 62 62
0 S 95 LCIL 85 93
0 B 96 LCIL 9 13
0 S 97 LCIL 30 43
0 C 75
0 C 38
0 S 98 LCIL 59 44
0 C 73
0 B 99 LCIL 67 7
0 C 64
0 B 100 LCIL 13 11
0 B 101 LCIL 54 5
0 C 32
0 S 102 LCIL 29 34
0 S 103 LCIL 74 46
0 B 104 LCIL 77 87
0 S 105 LCIL 58 78
0 C 86
0 B 106 LCIL 87 28
0 S 107 LCIL 30 26
0 C 48
0 S 108 LCIL 97 69
0 C 30
0 B 109 LCIL 90 48
0 S 110 LCIL 25 29
0 S 111 LCIL 31 99
0 B 112 LCIL 83 25
0 S 113 LCIL 85 85
0 B 114 LCIL 66 66
0 S 115 LCIL 6 58
0 S 116 LCIL 47 53
0 S 117 LCIL 88 92
0 S 118 LCIL 90 92
0 S 119 LCIL 68 27
0 C 49
0 S 120 LCIL 33 40
0 C 73
0 S 121 LCIL 6 43
0 B 122 LCIL 7 5
0 S 123 LCIL 41 46
0 B 124 LCIL 54 41
0 S 125 LCIL 9 85
0 C 53
0 B 126 LCIL 66 67
0 S 127 LCIL 68 23
0 B 128 LCIL 72 77
0 C 113
0 C 81
0 C 104
0 C 80
0 S 129 LCIL 58 79
0 C 47
0 B 130 LCIL 77 28
0 B 131 LCIL 78 45
0 C 53
0 S 132 LCIL 43 30
0 S 133 LCIL 13 53
0 C 81
0 B 134 LCIL 3 19
0 B 135 LCIL 36 25
0 B 136 LCIL 63 78
0 B 137 LCIL 75 81
0 B 138 LCIL 13 35
0 B 139 LCIL 31 4
0 B 140 LCIL 87 85
0 B 141 LCIL 72 2
0 S 142 LCIL 68 57
0 C 69
0 C 105
0 S 143 LCIL 85 1
0 S 144 LCIL 91 71
0 S 145 LCIL 25 29
0 S 146 LCIL 5 55
0 C 134
0 C 89
0 C 45
0 S 147 LCIL 1 85
0 C 140
0 C 77
0 S 148 LCIL 67 35
0 S 149 LCIL 59 83
0 B 150 LCIL 13 6
0 C 108
0 B 151 LCIL 64 71
0 B 152 LCIL 93 68
0 C 73
0 S 153 LCIL 83 75
0 C 99
0 C 29
0 S 154 LCIL 58 94
0 C 106
0 C 54
0 B 155 LCIL 19 44
0 S 156 LCIL 17 8
0 S 157 LCIL 8 56
0 S 158 LCIL 93 98
0 B 159 LCIL 10 63
0 S 160 LCIL 61 99
0 C 116
0 B 161 LCIL 74 18
0 S 162 LCIL 50 47
0 B 163 LCIL 10 98
0 C 61
0 S 164 LCIL 98 33
0 S 165 LCIL 71 32
0 B 166 LCIL 30 53
0 C 10
0 S 167 LCIL 47 34
0 S 168 LCIL 39 9
0 C 65
0 S 169 LCIL 31 99
0 C 93
0 S 170 LCIL 33 86
0 C 12
0 S 171 LCIL 11 37
0 S 172 LCIL 92 63
0 S 173 LCIL 15 70
0 C 120
0 B 174 LCIL 75 34
0 S 175 LCIL 22 29
0 S 176 LCIL 14 51
0 S 177 LCIL 14 43
0 B 178 LCIL 32 98
0 B 179 LCIL 13 15
0 C 137
0 C 29
0 S 180 LCIL 36 14
0 C 102
0 S 181 LCIL 58 73
0 B 182 LCIL 42 58
0 C 139
0 S 183 LCIL 80 78
0 B 184 LCIL 45 94
0 C 52
0 B 185 LCIL 57 38
0 S 186 LCIL 86 70
0 S 187 LCIL 31 75
0 B 188 LCIL 39 33
0 B 189 LCIL 13 47
0 C 117
0 S 190 LCIL 83 94
0 B 191 LCIL 92 79
0 S 192 LCIL 61 84
0 C 107
0 B 193 LCIL 60 51
0 B 194 LCIL 49 1
0 C 27
0 B 195 LCIL 49 84
0 B 196 LCIL 89 48
0 C 179
0 S 197 LCIL 82 35
0 S 198 LCIL 47 50
0 B 199 LCIL 54 91
0 C 167
0 S 200 LCIL 85 17
0 B 201 LCIL 83 64
0 C 85
0 B 202 LCIL 25 26
0 C 4
0 C 195
0 S 203 LCIL 4 44
0 B 204 LCIL 35 44
0 S 205 LCIL 84 19
0 C 74
0 C 163
0 S 206 LCIL 77 14
0 B 207 LCIL 11 9
0 B 208 LCIL 82 18
0 S 209 LCIL 87 2
0 S 210 LCIL 34 26
0 B 211 LCIL 29 49
0 S 212 LCIL 19 66
0 B 213 LCIL 44 94
0 S 214 LCIL 67 64
0 C 3
0 S 215 LCIL 37 51
0 B 216 LCIL 63 89
0 C 213
0 B 217 LCIL 17 59
0 S 218 LCIL 95 3
0 S 219 LCIL 99 70
0 C 214
0 B 220 LCIL 34 62
0 C 95
0 B 221 LCIL 18 47
0 C 202
0 C 12
0 C 25
0 S 222 LCIL 14 91
0 S 223 LCIL 92 33
0 B 224 LCIL 58 43
0 C 119
0 S 225 LCIL 25 58
0 S 226 LCIL 65 83
0 C 143
0 B 227 LCIL 1 29
0 S 228 LCIL 76 88
0 B 229 LCIL 7 14
0 S 230 LCIL 16 54
0 S 231 LCIL 53 54
0 B 232 LCIL 28 87
0 B 233 LCIL 50 11
0 S 234 LCIL 95 93
0 S 235 LCIL 58 19
0 C 30
0 B 236 LCIL 35 84
0 C 150
0 B 237 LCIL 51 65
0 C 197
0 C 6
0 B 238 LCIL 30 91
0 S 239 LCIL 22 34
0 C 186
0 S 240 LCIL 57 86
0 B 241 LCIL 89 44
0 C 61
0 B 242 LCIL 79 37
0 B 243 LCIL 7 71
0 B 244 LCIL 44 21
0 S 245 LCIL 96 54
0 B 246 LCIL 89 74
0 B 247 LCIL 41 99
0 C 56
0 S 248 LCIL 60 20
0 B 249 LCIL 40 28
0 B 250 LCIL 100 94
0 C 185
0 B 251 LCIL 59 47
0 C 124
0 C 179
0 B 252 LCIL 6 77
0 B 253 LCIL 41 71
0 C 137
0 C 68
0 B 254 LCIL 67 31
0 C 215
0 B 255 LCIL 36 55
0 C 175
0 C 103
0 C 169
0 S 256 LCIL 95 8
0 S 257 LCIL 19 47
0 C 12
0 S 258 LCIL 29 17
0 C 203
0 B 259 LCIL 70 49
0 C 78
0 S 260 LCIL 57 66
0 B 261 LCIL 13 85
0 B 262 LCIL 40 95
0 S 263 LCIL 28 56
0 B 264 LCIL 99 80
0 B 265 LCIL 78 84
0 B 266 LCIL 47 23
0 C 75
0 B 267 LCIL 30 87
0 S 268 LCIL 85 49
0 B 269 LCIL 60 40
0 C 93
0 S 270 LCIL 6 100
0 B 271 LCIL 87 82
0 B 272 LCIL 45 83
0 B 273 LCIL 7 16
0 S 274 LCIL 46 3
0 C 217
0 S 275 LCIL 45 1
0 B 276 LCIL 19 58
0 B 277 LCIL 77 77
0 S 278 LCIL 20 11
0 C 55
0 S 279 LCIL 92 17
0 B 280 LCIL 7 34
0 S 281 LCIL 3 35
0 C 256
0 S 282 LCIL 29 54
0 S 283 LCIL 92 30
0 B 284 LCIL 90 54
0 S 285 LCIL 55 46
0 S 286 LCIL 89 57
0 C 241
0 C 265
0 S 287 LCIL 13 9
0 S 288 LCIL 72 48
0 S 289 LCIL 80 60
0 C 34
0 C 185
0 B 290 LCIL 44 81
0 C 154
0 C 277
0 B 291 LCIL 37 58
0 B 292 LCIL 67 16
0 B 293 LCIL 85 84
0 S 294 LCIL 19 82
0 S 295 LCIL 60 54
0 B 296 LCIL 59 77
0 B 297 LCIL 94 48
0 C 8
0 B 298 LCIL 35 73
0 S 299 LCIL 80 24
0 S 300 LCIL 44 27
0 C 24
0 S 301 LCIL 67 55
0 S 302 LCIL 2 41
0 B 303 LCIL 10 48
0 C 225
0 B 304 LCIL 6 34
0 S 305 LCIL 32 50
0 C 142
0 C 79
0 S 306 LCIL 18 61
0 S 307 LCIL 11 80
0 B 308 LCIL 55 56
0 B 309 LCIL 1 9
0 B 310 LCIL 33 31
0 S 311 LCIL 84 23
0 C 48
0 S 312 LCIL 32 80
0 B 313 LCIL 99 78
0 S 314 LCIL 96 94
0 C 201
0 S 315 LCIL 78 14
0 C 49
0 C 217
0 C 171
0 B 316 LCIL 23 21
0 S 317 LCIL 20 51
0 S 318 LCIL 21 98
0 S 319 LCIL 50 98
0 S 320 LCIL 93 23
0 C 237
0 B 321 LCIL 17 96
0 C 275
0 S 322 LCIL 73 47
0 B 323 LCIL 33 98
0 S 324 LCIL 17 51
0 S 325 LCIL 24 93
0 S 326 LCIL 19 37
0 S 327 LCIL 86 2
0 S 328 LCIL 8 18
0 B 329 LCIL 24 48
0 C 33
0 S 330 LCIL 78 52
0 C 294
0 B 331 LCIL 77 69
0 S 332 LCIL 59 62
0 B 333 LCIL 18 22
0 S 334 LCIL 80 42
0 B 335 LCIL 44 6
0 B 336 LCIL 11 40
0 C 192
0 B 337 LCIL 38 69
0 C 19
0 B 338 LCIL 40 86
0 C 50
0 S 339 LCIL 61 22
0 B 340 LCIL 81 39
0 B 341 LCIL 85 100
0 S 342 LCIL 46 9
0 B 343 LCIL 72 24
0 B 344 LCIL 88 1
0 S 345 LCIL 96 95
0 S 346 LCIL 66 47
0 C 17
0 C 76
0 B 347 LCIL 91 11
0 C 285
0 B 348 LCIL 27 20
0 C 66
0 C 188
0 C 60
0 B 349 LCIL 58 37
0 S 350 LCIL 16 57
0 S 351 LCIL 38 81
0 B 352 LCIL 87 49
0 B 353 LCIL 92 63
0 C 348
0 B 354 LCIL 26 54
0 S 355 LCIL 85 33
0 C 35
0 S 356 LCIL 79 40
0 S 357 LCIL 20 43
0 C 263
0 B 358 LCIL 51 21
0 S 359 LCIL 3 64
0 S 360 LCIL 29 30
0 B 361 LCIL 74 24
0 C 146
0 S 362 LCIL 23 16
0 B 363 LCIL 66 43
0 B 364 LCIL 57 97
0 S 365 LCIL 5 4
0 S 366 LCIL 25 67
0 B 367 LCIL 68 45
0 S 368 LCIL 94 55
