test.in
2
o 
1 S 1 GOOG 2 1 
1 S 2 GOOG 2 1 
1 S 3 GOOG 2 1 
1 S 4 GOOG 2 1 
1 S 5 GOOG 2 1  
1 S 6 GOOG 2 1 
1 S 7 GOOG 2 1 
1 S 8 GOOG 2 1 
1 S 9 GOOG 2 1 
1 S 10 GOOG 2 1 
1 S 11 GOOG 2 1 
1 S 12 GOOG 2 1 
1 S 13 GOOG 2 1
.
0 B 14 GOOG 100 100 
1 S 15 GOOG 1 1 
1 S 16 GOOG 1 1 
1 S 17 GOOG 1 1 
x
